Workbook

Sheet Holdings
A1: Period | C1: Non-residents | D1: Banks | E1: Insurers | F1: Local pension funds | G1: Other financial institutions | H1: Other
A2: 2006: | C2: 0.0859 | D2: 0.1398853 | E2: 0.10038666 | F2: 0.44793512 | G2: 0.21052332 | H2: 0.015349075
A3: 2007: | C3: 0.1042 | D3: 0.16281961 | E3: 0.13024001 | F3: 0.46416801 | G3: 0.11960529 | H3: 0.018993808
A4: 2008: | C4: 0.12837598 | D4: 0.18001583 | E4: 0.13663033 | F4: 0.43894899 | G4: 0.10222481 | H4: 0.013804053
A5: 2009: | C5: 0.1377 | D5: 0.18269688 | E5: 0.12427388 | F5: 0.39932637 | G5: 0.13207275 | H5: 0.02392689
A6: 2010: | C6: 0.21768879 | D6: 0.1771325 | E6: 0.1414503 | F6: 0.36454108 | G6: 0.08111558 | H6: 0.018071749
A7: 2011: | B7: January | C7: 0.22584501 | D7: 0.17052056 | E7: 0.14102996 | F7: 0.36940927 | G7: 0.07141512 | H7: 0.02178009
B8: March | C8: 0.22820052 | D8: 0.16342779 | E8: 0.13390941 | F8: 0.37984411 | G8: 0.061368209 | H8: 0.033249951
B9: May | C9: 0.26120833 | D9: 0.16540425 | E9: 0.12712703 | F9: 0.35804421 | G9: 0.060345767 | H9: 0.027870423
B10: June | C10: 0.26903586 | D10: 0.16649035 | E10: 0.12353169 | F10: 0.35310629 | G10: 0.060924952 | H10: 0.026910855
B11: July | C11: 0.2750472 | D11: 0.16895604 | E11: 0.12511784 | F11: 0.34519957 | G11: 0.059455437 | H11: 0.026223899
B12: August | C12: 0.29091739 | D12: 0.16600833 | E12: 0.11883232 | F12: 0.33393496 | G12: 0.064518522 | H12: 0.025788477
B13: September | C13: 0.28334261 | D13: 0.16746176 | E13: 0.11619403 | F13: 0.33766462 | G13: 0.073745856 | H13: 0.021591131
B14: October | C14: 0.2883532 | D14: 0.16513262 | E14: 0.11510528 | F14: 0.33688693 | G14: 0.073056578 | H14: 0.021465397
B15: November | C15: 0.28752425 | D15: 0.16126966 | E15: 0.11635385 | F15: 0.33617037 | G15: 0.07625016 | H15: 0.022431707
B16: December | C16: 0.28608451 | D16: 0.16924442 | E16: 0.11579287 | F16: 0.33325085 | G16: 0.074773662 | H16: 0.020853692
A17: 2012: | B17: January | C17: 0.29064915 | D17: 0.16274993 | E17: 0.11644014 | F17: 0.32946074 | G17: 0.079670151 | H17: 0.021029891
B18: February | C18: 0.2956 | D18: 0.1713 | E18: 0.111 | F18: 0.3239 | G18: 0.0759 | H18: 0.0222
B19: March | C19: 0.2924 | D19: 0.1702 | E19: 0.1154 | F19: 0.3243 | G19: 0.0757 | H19: 0.022
B20: April | C20: 0.3104 | D20: 0.1669 | E20: 0.1108 | F20: 0.3204 | G20: 0.0688 | H20: 0.0226
B21: May | C21: 0.315 | D21: 0.1723 | E21: 0.1085 | F21: 0.315 | G21: 0.0676 | H21: 0.0217
B22: June | C22: 0.3199 | D22: 0.1775 | E22: 0.1108 | F22: 0.3094 | G22: 0.0607 | H22: 0.0215
B23: July | C23: 0.3333 | D23: 0.1759 | E23: 0.1041 | F23: 0.3062 | G23: 0.0582 | H23: 0.022
B24: August | C24: 0.3272 | D24: 0.1784 | E24: 0.099 | F24: 0.3053 | G24: 0.066 | H24: 0.0238
B25: September | C25: 0.3331 | D25: 0.1739 | E25: 0.1035 | F25: 0.302 | G25: 0.0649 | H25: 0.023
B26: October | C26: 0.3518 | D26: 0.1639 | E26: 0.0959 | F26: 0.3001 | G26: 0.0649 | H26: 0.0234
B27: November | C27: 0.3497 | D27: 0.1651 | E27: 0.0971 | F27: 0.2964 | G27: 0.0679 | H27: 0.0238
B28: December | C28: 0.3588 | D28: 0.1701 | E28: 0.1408 | F28: 0.2516 | G28: 0.0578 | H28: 0.0209
A29: 2013: | B29: January | C29: 0.365 | D29: 0.1686 | E29: 0.0893 | F29: 0.2968 | G29: 0.0617 | H29: 0.01842
B30: February | C30: 0.36868489 | D30: 0.16327626 | E30: 0.084976228 | F30: 0.28072112 | G30: 0.067730078 | H30: 0.034611422
B31: March | C31: 0.38013154 | D31: 0.14221125 | E31: 0.088187465 | F31: 0.2906114 | G31: 0.066615748 | H31: 0.032242601
B32: April | C32: 0.38693613 | D32: 0.14913184 | E32: 0.081306312 | F32: 0.28565773 | G32: 0.065704441 | H32: 0.031263557
B33: May | C33: 0.38200297 | D33: 0.14654284 | E33: 0.08046472 | F33: 0.28414198 | G33: 0.074095477 | H33: 0.032752014
B34: June | C34: 0.36698699 | D34: 0.14580192 | E34: 0.09001753 | F34: 0.28612063 | G34: 0.079905023 | H34: 0.031167899
B35: July | C35: 0.37139827 | D35: 0.14864921 | E35: 0.084694808 | F35: 0.28993934 | G35: 0.07348656 | H35: 0.031831813
B36: August | C36: 0.37251525 | D36: 0.14243383 | E36: 0.085089289 | F36: 0.29090586 | G36: 0.077910444 | H36: 0.031145327
B37: September | C37: 0.374 | D37: 0.139 | E37: 0.089 | F37: 0.289 | G37: 0.078 | H37: 0.031
B38: October | C38: 0.377 | D38: 0.1368 | E38: 0.0869 | F38: 0.2894 | G38: 0.0781 | H38: 0.0311
B39: December | C39: 0.36391866 | D39: 0.14580696 | E39: 0.08570016 | F39: 0.29221132 | G39: 0.081599951 | H39: 0.030762944
A40: 2014: | B40: January | C40: 0.357 | D40: 0.143 | E40: 0.085 | F40: 0.3 | G40: 0.085 | H40: 0.03
...

Sheet Fixed rate bond (Values)
A1: 28 March 2024
B2: Sector code | C2: R186 (2026) | D2: R2030 (2030) | E2: R213 (2031) | F2: R2032 (2032) | G2: R2035 (2035) | H2: R209 (2036) | I2: R2037 (2037) | J2: R2040 (2040) | K2: R214 (2041) | L2: R2044 (2044) | M2: R2048 (2048) | N2: R2053 (2053) | O2: Total
B3: Foreign sector | C3: 1.2155885e+11 | D3: 96252878157 | E3: 61718043483 | F3: 75993240498 | G3: 96058442580 | H3: 35353761063 | I3: 90751641821 | J3: 72393759371 | K3: 46326544335 | L3: 71355125804 | M3: 96528745729 | N3: 6842650009 | O3: =SUM(C3:N3) -> 8.7113369e+11
B4: Monetary institutions | C4: 1.0913493e+11 | D4: 7.4231442e+10 | E4: 52069917418 | F4: 7.2639768e+10 | G4: 3.3025839e+10 | H4: 13174475750 | I4: 2.4581395e+10 | J4: 34889328622 | K4: 13107090621 | L4: 3.1571669e+10 | M4: 1.3066631e+11 | N4: 5227043517 | O4: =SUM(C4:N4) -> 5.9431921e+11
B5: Long-term insurers | C5: 1.804311e+10 | D5: 15801504057 | E5: 8445130190 | F5: 15024364830 | G5: 18842483430 | H5: 6797005144 | I5: 19625965931 | J5: 21653054238 | K5: 5756673606 | L5: 20298766048 | M5: 23624663548 | N5: 8267005575 | O5: =SUM(C5:N5) -> 1.8217973e+11
B6: Short-term insurers | C6: 3079283765 | D6: 3889289374 | E6: 1922115834 | F6: 3383519235 | G6: 3469440671 | H6: 638683955 | I6: 3223977839 | J6: 2196984700 | K6: 705759315 | L6: 1425696459 | M6: 3745452362 | N6: 117705000 | O6: =SUM(C6:N6) -> 27797908509
B7: Private self-administered funds | C7: 2.8465597e+09 | D7: 5215813287 | E7: 3945572797 | F7: 10483170644 | G7: 10106921680 | H7: 3940397401 | I7: 9209020775 | J7: 7668388461 | K7: 1760075448 | L7: 7726667095 | M7: 9413401632 | N7: 809506137 | O7: =SUM(C7:N7) -> 7.3125495e+10
B8: Official pension funds | C8: 2.1317189e+10 | D8: 50003942310 | E8: 19919558849 | F8: 50254797688 | G8: 50455111003 | H8: 15213940778 | I8: 58181192183 | J8: 39513065994 | K8: 8721167707 | L8: 50370009571 | M8: 67609308668 | N8: 4348803773 | O8: =SUM(C8:N8) -> 4.3590809e+11
B9: Other financial institutions | C9: 6.7283874e+10 | D9: 9.3397905e+10 | E9: 42093385662 | F9: 79063392600 | G9: 9.2049958e+10 | H9: 24511517592 | I9: 76182731998 | J9: 58713744967 | K9: 15489995533 | L9: 71497638839 | M9: 7.4010641e+10 | N9: 17247526285 | O9: =SUM(C9:N9) -> 7.1154231e+11
B10: Other sector | C10: 1.3864944e+10 | D10: 14336910839 | E10: 1650737011 | F10: 6.5186679e+09 | G10: 7618685368 | H10: 4628770462 | I10: 4.5884229e+09 | J10: 5514539298 | K10: 1514549931 | L10: 2.0210582e+09 | M10: 2321880005 | N10: 382431412 | O10: =SUM(C10:N10) -> 6.4961597e+10
B11: CSDP reporting error | C11: 7.0100744e+08 | D11: 338974693 | E11: 6700000 | F11: 6570000 | G11: 325958440 | H11: 4000000 | I11: 1618300 | J11: 14482150 | K11: 0 | L11: 6880000 | M11: 0 | N11: 0 | O11: =SUM(C11:N11) -> 1.406191e+09
C12: =SUM(C3:C11) -> 3.5782976e+11 | D12: =SUM(D3:D11) -> 353468660031 | E12: =SUM(E3:E11) -> 191771161244 | F12: =SUM(F3:F11) -> 313367490951 | G12: =SUM(G3:G11) -> 311952840328 | H12: =SUM(H3:H11) -> 104262552145 | I12: =SUM(I3:I11) -> 286345967029 | J12: =SUM(J3:J11) -> 242557347801 | ... O12: =SUM(O3:O11) -> 2.9623742e+12

Sheet Fixed rate bond % (Values)
A1: ='Fixed rate bond (Values)'!A1 -> 28 March 2024
B2: Sector code | C2: R186 (2026) | D2: R2030 (2030) | E2: R213 (2031) | F2: R2032 (2032) | G2: R2035 (2035) | H2: R209 (2036) | I2: R2037 (2037) | J2: R2040 (2040) | K2: R214 (2041) | L2: R2044 (2044) | M2: R2048 (2048) | N2: R2053 (2053) | O2: TOTAL
B3: Foreign sector | C3: 0.33971142 | D3: 0.27230951 | E3: 0.32183172 | F3: 0.24250518 | G3: 0.30792617 | H3: 0.33908398 | I3: 0.31693005 | J3: 0.29846038 | K3: 0.49609792 | L3: 0.27843348 | M3: 0.23663623 | N3: 0.15823837 | O3: 0.29406605
B4: Monetary institutions | C4: 0.30499122 | D4: 0.21000855 | E4: 0.2715211 | F4: 0.23180378 | G4: 0.10586805 | H4: 0.12635865 | I4: 0.08584509 | J4: 0.1438395 | K4: 0.14036014 | L4: 0.12319521 | M4: 0.32032305 | N4: 0.12087698 | O4: 0.2006226
B5: Long-term insurers | C5: 0.050423728 | D5: 0.044704116 | E5: 0.04403754 | F5: 0.047944874 | G5: 0.060401705 | H5: 0.065191241 | I5: 0.068539348 | J5: 0.089269834 | K5: 0.061646596 | L5: 0.079207429 | M5: 0.057914886 | N5: 0.19117703 | O5: 0.061497878
B6: Short-term insurers | C6: 0.0086054435 | D6: 0.011003209 | E6: 0.010022966 | F6: 0.010797289 | G6: 0.011121683 | H6: 0.0061257272 | I6: 0.01125903 | J6: 0.0090575887 | K6: 0.0075577777 | L6: 0.0055631831 | M6: 0.0091818217 | N6: 0.0027219641 | O6: 0.0093836587
B7: Private self-administered funds | C7: 0.0079550671 | D7: 0.014756084 | E7: 0.02057438 | F7: 0.033453281 | G7: 0.032398877 | H7: 0.037793027 | I7: 0.03216047 | J7: 0.031614744 | K7: 0.018848152 | L7: 0.030150081 | M7: 0.023076565 | N7: 0.018720077 | O7: 0.02468476
B8: Official pension funds | C8: 0.059573549 | D8: 0.14146641 | E8: 0.1038715 | F8: 0.16037017 | G8: 0.16173955 | H8: 0.14591951 | I8: 0.20318495 | J8: 0.16290195 | K8: 0.093392529 | L8: 0.19654786 | M8: 0.16574143 | N8: 0.10056742 | O8: 0.14714822
B9: Other financial institutions | C9: 0.1880332 | D9: 0.26423249 | E9: 0.219498 | F9: 0.25230247 | G9: 0.29507652 | H9: 0.23509416 | I9: 0.26605135 | J9: 0.24206129 | K9: 0.165878 | L9: 0.27898958 | M9: 0.18143403 | N9: 0.39885432 | O9: 0.24019326
B10: Other sector | C10: 0.03874732 | D10: 0.040560628 | E10: 0.008607848 | F10: 0.020801992 | G10: 0.024422555 | H10: 0.044395331 | I10: 0.016024053 | J10: 0.022734992 | K10: 0.016218889 | L10: 0.007886333 | M10: 0.0056919929 | N10: 0.0088438433 | O10: 0.021928896
B11: CSDP reporting error | C11: 0.001959053 | D11: 0.00095899504 | E11: 3.4937474e-05 | F11: 2.09658e-05 | G11: 0.0010448965 | H11: 3.8364685e-05 | I11: 5.6515551e-06 | J11: 5.9706087e-05 | K11: 0 | L11: 2.6846317e-05 | M11: 0 | N11: 0 | O11: 0.00047468379
C12: =SUM(C3:C11) -> 1 | D12: =SUM(D3:D11) -> 1 | E12: =SUM(E3:E11) -> 1 | F12: =SUM(F3:F11) -> 1 | G12: =SUM(G3:G11) -> 1 | H12: =SUM(H3:H11) -> 1 | I12: =SUM(I3:I11) -> 1 | J12: =SUM(J3:J11) -> 1 | ... O12: =SUM(O3:O11) -> 1

Sheet ILB (Values)
A1: ='Fixed rate bond (Values)'!A1 -> 28 March 2024
B2: Sector code | C2: I2025 (2025) | D2: R210 (2028) | E2: I2029 (2029) | F2: I2031 (2031) | G2: I2033 (2033) | H2: R202 (2033) | I2: I2038 (2038) | J2: I2043 (2043) | K2: I2046 (2046) | L2: I2050 (2050) | M2: I2058 (2058) | N2: Amount
B3: Foreign sector | C3: 1180653612 | D3: 73947432 | E3: 4587472366 | F3: 145800000 | G3: 13689166658 | H3: 406701358 | I3: 3218578152 | J3: 20000000 | K3: 6677936123 | L3: 2347482384 | M3: 105000000 | N3: =SUM(C3:M3) -> 32452738085
B4: Monetary institutions | C4: 11292017762 | D4: 1322991644 | E4: 2831508051 | F4: 134298985 | G4: 1725115804 | H4: 4.0141131e+09 | I4: 6404023278 | J4: 785000 | K4: 1.5665272e+10 | L4: 1.080128e+10 | M4: 67668782 | N4: =SUM(C4:M4) -> 5.4259074e+10
B5: Long-term insurers | C5: 4.7216795e+09 | D5: 2255043386 | E5: 3082744732 | F5: 84200000 | G5: 3178264955 | H5: 1749739737 | I5: 5817713026 | J5: 0 | K5: 6464951440 | L5: 7301800354 | M5: 0 | N5: =SUM(C5:M5) -> 3.4656137e+10
B6: Short-term insurers | C6: 1.8137078e+09 | D6: 369807999 | E6: 1030798093 | F6: 8000000 | G6: 1253324184 | H6: 521524008 | I6: 1.464691e+09 | J6: 0 | K6: 1321977400 | L6: 2.2503744e+09 | M6: 0 | N6: =SUM(C6:M6) -> 1.0034205e+10
B7: Private self-administered funds | C7: 4131105488 | D7: 2.247758e+09 | E7: 4172371208 | F7: 0 | G7: 7486974655 | H7: 3.0879178e+09 | I7: 10835327746 | J7: 108000000 | K7: 14098071947 | L7: 1.9130227e+10 | M7: 119400000 | N7: =SUM(C7:M7) -> 6.5417154e+10
B8: Official pension funds | C8: 12014681229 | D8: 19677358590 | E8: 31749909590 | F8: 430000000 | G8: 36999450579 | H8: 23043712576 | I8: 49921994138 | J8: 6282000000 | K8: 43795986821 | L8: 51159359495 | M8: 1610000000 | N8: =SUM(C8:M8) -> 276684453018
B9: Other financial institutions | C9: 19591141450 | D9: 5.2676427e+09 | E9: 18522153112 | F9: 865734688 | G9: 13279116120 | H9: 4.2322128e+09 | I9: 5.8533286e+09 | J9: 42162416 | K9: 6.0351842e+09 | L9: 1.1112349e+10 | M9: 339858049 | N9: =SUM(C9:M9) -> 8.5140883e+10
B10: Other sector | C10: 1040013160 | D10: 6.9296781e+08 | E10: 795301406 | F10: 16966327 | G10: 843248358 | H10: 885263678 | I10: 1728810883 | J10: 0 | K10: 2560620122 | L10: 3127127558 | M10: 0 | N10: =SUM(C10:M10) -> 1.1690319e+10
B11: CSDP reporting error | C11: 0 | D11: 300000 | E11: 0 | F11: 0 | G11: 0 | H11: 0 | I11: 0 | J11: 0 | K11: 0 | L11: 0 | M11: 0 | N11: =SUM(C11:M11) -> 300000
C12: =SUM(C3:C11) -> 55785000000 | D12: =SUM(D3:D11) -> 31907817562 | E12: =SUM(E3:E11) -> 66772258558 | F12: =SUM(F3:F11) -> 1685000000 | G12: =SUM(G3:G11) -> 78454661313 | H12: =SUM(H3:H11) -> 37941184999 | I12: =SUM(I3:I11) -> 85244466840 | J12: =SUM(J3:J11) -> 6452947416 | ... N12: =SUM(N3:N11) -> 570335263519

Sheet ILB % (Values)
A1: ='Fixed rate bond (Values)'!A1 -> 28 March 2024
C2: I2025 (2025) | D2: R210 (2028) | E2: I2029 (2029) | F2: I2031 (2031) | G2: I2033 (2033) | H2: R202 (2033) | I2: I2038 (2038) | J2: I2043 (2043) | K2: I2046 (2046) | L2: I2050 (2050) | M2: I2058 (2058) | N2: TOTAL
B3: Foreign sector | C3: 0.021164356 | D3: 0.0023175334 | E3: 0.068703268 | F3: 0.08652819 | G3: 0.17448506 | H3: 0.010719258 | I3: 0.037757033 | J3: 0.0030993589 | K3: 0.069115464 | L3: 0.02189203 | M3: 0.046834713 | N3: 0.05690116
B4: Monetary institutions | C4: 0.20242032 | D4: 0.041462931 | E4: 0.042405456 | F4: 0.079702662 | G4: 0.021988697 | H4: 0.10579831 | I4: 0.075125384 | J4: 0.00012164984 | K4: 0.16213281 | L4: 0.10073002 | M4: 0.030183314 | N4: 0.095135401
B5: Long-term insurers | C5: 0.084640666 | D5: 0.070673696 | E5: 0.046168046 | F5: 0.049970326 | G5: 0.040510849 | H5: 0.046117161 | I5: 0.068247398 | J5: 0 | K5: 0.06691111 | L5: 0.068094753 | M5: 0 | N5: 0.0607645
B6: Short-term insurers | C6: 0.032512463 | D6: 0.011589887 | E6: 0.01543752 | F6: 0.0047477745 | G6: 0.01597514 | H6: 0.013745591 | I6: 0.017182242 | J6: 0 | K6: 0.013682233 | L6: 0.020986426 | M6: 0 | N6: 0.01759352
B7: Private self-administered funds | C7: 0.074054056 | D7: 0.070445369 | E7: 0.062486597 | F7: 0 | G7: 0.09543059 | H7: 0.081386961 | I7: 0.12710887 | J7: 0.016736538 | K7: 0.14591256 | L7: 0.17840369 | M7: 0.05325776 | N7: 0.11469947
B8: Official pension funds | C8: 0.21537476 | D8: 0.61669397 | E8: 0.47549552 | F8: 0.25519288 | G8: 0.47160296 | H8: 0.60735353 | I8: 0.58563325 | J8: 0.97350863 | K8: 0.45328076 | L8: 0.47709931 | M8: 0.71813227 | N8: 0.48512598
B9: Other financial institutions | C9: 0.35119013 | D9: 0.16508941 | E9: 0.27739294 | F9: 0.51378913 | G9: 0.16925847 | H9: 0.11154667 | I9: 0.068665202 | J9: 0.006533823 | K9: 0.062463095 | L9: 0.10363097 | M9: 0.15159195 | N9: 0.14928216
B10: Other sector | C10: 0.01864324 | D10: 0.021717807 | E10: 0.011910656 | F10: 0.010069037 | G10: 0.010748225 | H10: 0.023332526 | I10: 0.020280623 | J10: 0 | K10: 0.026501968 | L10: 0.029162805 | M10: 0 | N10: 0.020497276
B11: CSDP reporting error | C11: 0 | D11: 9.4020846e-06 | E11: 0 | F11: 0 | G11: 0 | H11: 0 | I11: 0 | J11: 0 | K11: 0 | L11: 0 | M11: 0 | N11: 5.260064e-07
C12: =SUM(C3:C11) -> 1 | D12: =SUM(D3:D11) -> 1 | E12: =SUM(E3:E11) -> 1 | F12: =SUM(F3:F11) -> 1 | G12: =SUM(G3:G11) -> 1 | H12: =SUM(H3:H11) -> 1 | I12: =SUM(I3:I11) -> 1 | J12: =SUM(J3:J11) -> 1 | ... N12: =SUM(N3:N11) -> 1

Sheet FRN (Values)
A1: ='Fixed rate bond (Values)'!A1 -> 28 March 2024
B2: Sector code | C2: RN2027 (2027) | D2: RN2030 (2030) | E2: Total
B3: Foreign sector | C3: 444814011 | D3: 267520000 | E3: =SUM(C3:D3) -> 712334011
B4: Monetary institutions | C4: 54309000000 | D4: 25597050000 | E4: =SUM(C4:D4) -> 79906050000
B5: Long-term insurers | C5: 1333750000 | D5: 1591870000 | E5: =SUM(C5:D5) -> 2925620000
B6: Short-term insurers | C6: 1399400000 | D6: 216680000 | E6: =SUM(C6:D6) -> 1616080000
B7: Private self-administered funds | C7: 95414000 | D7: 160606932 | E7: =SUM(C7:D7) -> 256020932
B8: Official pension funds | C8: 44530000 | D8: 75728094 | E8: =SUM(C8:D8) -> 120258094
B9: Other financial institutions | C9: 13268493386 | D9: 19256145572 | E9: =SUM(C9:D9) -> 32524638958
B10: Other sector | C10: 179598603 | D10: 99399402 | E10: =SUM(C10:D10) -> 278998005
B11: CSDP reporting error | C11: 0 | D11: 0 | E11: =SUM(C11:D11) -> 0
C12: =SUM(C3:C11) -> 71075000000 | D12: =SUM(D3:D11) -> 47265000000 | E12: 118340000000

Sheet FRN % (Values)
A1: ='Fixed rate bond (Values)'!A1 -> 28 March 2024
B3: Sector code | C3: RN2027 (2027) | D3: RN2030 (2030) | E3: TOTAL
B4: Foreign sector | C4: 0.0062583751 | D4: 0.0056600021 | E4: 0.0060193849
B5: Monetary institutions | C5: 0.76410834 | D5: 0.54156458 | E5: 0.67522435
B6: Long-term insurers | C6: 0.018765389 | D6: 0.033679678 | E6: 0.024722156
B7: Short-term insurers | C7: 0.019689061 | D7: 0.0045843648 | E7: 0.013656245
B8: Private self-administered funds | C8: 0.0013424411 | D8: 0.0033980098 | E8: 0.0021634353
B9: Official pension funds | C9: 0.00062652128 | D9: 0.0016022023 | E9: 0.0010162083
B10: Other financial institutions | C10: 0.18668299 | D10: 0.40740814 | E10: 0.27484062
B11: Other sector | C11: 0.0025268885 | D11: 0.0021030234 | E11: 0.0023575968
B12: CSDP reporting error | C12: 0 | D12: 0 | E12: 0
C13: =SUM(C4:C12) -> 1 | D13: =SUM(D4:D12) -> 1 | E13: =SUM(E4:E12) -> 1

Sheet Sukuk (Values)
A1: ='FRN % (Values)'!A1 -> 28 March 2024
B2: Sector code | C2: RS2029 (2029) | D2: RS2031 (2031) | E2: RS2034 (2034) | F2: RS2036 (2036) | G2: Total
B3: Foreign sector | C3: 0 | D3: 0 | E3: 0 | F3: 0 | G3: 0
B4: Monetary institutions | C4: 5710300000 | D4: 7660000000 | E4: 1300000000 | F4: 630000000 | G4: =SUM(C4:F4) -> 15300300000
B5: Long-term insurers | C5: 0 | D5: 30700000 | E5: 30700000 | F5: 0 | G5: =SUM(C5:F5) -> 61400000
B6: Short-term insurers | C6: 0 | D6: 0 | E6: 0 | F6: 0 | G6: =SUM(C6:F6) -> 0
B7: Private self-administered funds | C7: 0 | D7: 8500000 | E7: 8500000 | F7: 0 | G7: =SUM(C7:F7) -> 17000000
B8: Official pension funds | C8: 35000000 | D8: 40000000 | E8: 97000000 | F8: 138000000 | G8: =SUM(C8:F8) -> 310000000
B9: Other financial institutions | C9: 1744700000 | D9: 1118635400 | E9: 1040710000 | F9: 783000000 | G9: =SUM(C9:F9) -> 4687045400
B10: Other sector | C10: 0 | D10: 8164600 | E10: 2090000 | F10: 0 | G10: =SUM(C10:F10) -> 10254600
B11: CSDP reporting error | C11: 0 | D11: 0 | E11: 0 | F11: 0 | G11: =SUM(C11:F11) -> 0
C12: =SUM(C3:C11) -> 7490000000 | D12: =SUM(D3:D11) -> 8866000000 | E12: =SUM(E3:E11) -> 2479000000 | F12: =SUM(F3:F11) -> 1551000000 | G12: =SUM(G3:G11) -> 20386000000

Sheet Sukuk % (Values)
A1: ='Sukuk (Values)'!A1 -> 28 March 2024
B2: Sector code | C2: RS2029 (2029) | D2: RS2031 (2031) | E2: RS2034 (2034) | F2: RS2036 (2036) | G2: TOTAL
B3: Foreign sector | C3: 0 | D3: 0 | E3: 0 | F3: 0 | G3: 0
B4: Monetary institutions | C4: 0.76238985 | D4: 0.86397473 | E4: 0.524405 | F4: 0.40618956 | G4: 0.75052978
B5: Long-term insurers | C5: 0 | D5: 0.0034626664 | E5: 0.012384026 | F5: 0 | G5: 0.0030118709
B6: Short-term insurers | C6: 0 | D6: 0 | E6: 0 | F6: 0 | G6: 0
B7: Private self-administered funds | C7: 0 | D7: 0.0009587187 | E7: 0.0034288019 | F7: 0 | G7: 0.00083390562
B8: Official pension funds | C8: 0.0046728972 | D8: 0.0045116174 | E8: 0.039128681 | F8: 0.088974855 | G8: 0.015206514
B9: Other financial institutions | C9: 0.23293725 | D9: 0.12617137 | E9: 0.41981041 | F9: 0.50483559 | G9: 0.22991491
B10: Other sector | C10: 0 | D10: 0.00092088879 | E10: 0.00084308189 | F10: 0 | G10: 0.00050302168
B11: CSDP reporting error | C11: 0 | D11: 0 | E11: 0 | F11: 0 | G11: 0
C12: =SUM(C3:C11) -> 1 | D12: =SUM(D3:D11) -> 1 | E12: =SUM(E3:E11) -> 1 | F12: =SUM(F3:F11) -> 1 | G12: =SUM(G3:G11) -> 1
