Workbook

Sheet Holdings
A1: Period | C1: Non-residents | D1: Banks | E1: Insurers | F1: Local pension funds | G1: Other financial institutions | H1: Other
A2: 2006: | C2: 0.0859 | D2: 0.1398853 | E2: 0.10038666 | F2: 0.44793512 | G2: 0.21052332 | H2: 0.015349075
A3: 2007: | C3: 0.1042 | D3: 0.16281961 | E3: 0.13024001 | F3: 0.46416801 | G3: 0.11960529 | H3: 0.018993808
A4: 2008: | C4: 0.12837598 | D4: 0.18001583 | E4: 0.13663033 | F4: 0.43894899 | G4: 0.10222481 | H4: 0.013804053
A5: 2009: | C5: 0.1377 | D5: 0.18269688 | E5: 0.12427388 | F5: 0.39932637 | G5: 0.13207275 | H5: 0.02392689
A6: 2010: | C6: 0.21768879 | D6: 0.1771325 | E6: 0.1414503 | F6: 0.36454108 | G6: 0.08111558 | H6: 0.018071749
A7: 2011: | B7: January | C7: 0.22584501 | D7: 0.17052056 | E7: 0.14102996 | F7: 0.36940927 | G7: 0.07141512 | H7: 0.02178009
B8: March | C8: 0.22820052 | D8: 0.16342779 | E8: 0.13390941 | F8: 0.37984411 | G8: 0.061368209 | H8: 0.033249951
B9: May | C9: 0.26120833 | D9: 0.16540425 | E9: 0.12712703 | F9: 0.35804421 | G9: 0.060345767 | H9: 0.027870423
B10: June | C10: 0.26903586 | D10: 0.16649035 | E10: 0.12353169 | F10: 0.35310629 | G10: 0.060924952 | H10: 0.026910855
B11: July | C11: 0.2750472 | D11: 0.16895604 | E11: 0.12511784 | F11: 0.34519957 | G11: 0.059455437 | H11: 0.026223899
B12: August | C12: 0.29091739 | D12: 0.16600833 | E12: 0.11883232 | F12: 0.33393496 | G12: 0.064518522 | H12: 0.025788477
B13: September | C13: 0.28334261 | D13: 0.16746176 | E13: 0.11619403 | F13: 0.33766462 | G13: 0.073745856 | H13: 0.021591131
B14: October | C14: 0.2883532 | D14: 0.16513262 | E14: 0.11510528 | F14: 0.33688693 | G14: 0.073056578 | H14: 0.021465397
B15: November | C15: 0.28752425 | D15: 0.16126966 | E15: 0.11635385 | F15: 0.33617037 | G15: 0.07625016 | H15: 0.022431707
B16: December | C16: 0.28608451 | D16: 0.16924442 | E16: 0.11579287 | F16: 0.33325085 | G16: 0.074773662 | H16: 0.020853692
A17: 2012: | B17: January | C17: 0.29064915 | D17: 0.16274993 | E17: 0.11644014 | F17: 0.32946074 | G17: 0.079670151 | H17: 0.021029891
B18: February | C18: 0.2956 | D18: 0.1713 | E18: 0.111 | F18: 0.3239 | G18: 0.0759 | H18: 0.0222
B19: March | C19: 0.2924 | D19: 0.1702 | E19: 0.1154 | F19: 0.3243 | G19: 0.0757 | H19: 0.022
B20: April | C20: 0.3104 | D20: 0.1669 | E20: 0.1108 | F20: 0.3204 | G20: 0.0688 | H20: 0.0226
B21: May | C21: 0.315 | D21: 0.1723 | E21: 0.1085 | F21: 0.315 | G21: 0.0676 | H21: 0.0217
B22: June | C22: 0.3199 | D22: 0.1775 | E22: 0.1108 | F22: 0.3094 | G22: 0.0607 | H22: 0.0215
B23: July | C23: 0.3333 | D23: 0.1759 | E23: 0.1041 | F23: 0.3062 | G23: 0.0582 | H23: 0.022
B24: August | C24: 0.3272 | D24: 0.1784 | E24: 0.099 | F24: 0.3053 | G24: 0.066 | H24: 0.0238
B25: September | C25: 0.3331 | D25: 0.1739 | E25: 0.1035 | F25: 0.302 | G25: 0.0649 | H25: 0.023
B26: October | C26: 0.3518 | D26: 0.1639 | E26: 0.0959 | F26: 0.3001 | G26: 0.0649 | H26: 0.0234
B27: November | C27: 0.3497 | D27: 0.1651 | E27: 0.0971 | F27: 0.2964 | G27: 0.0679 | H27: 0.0238
B28: December | C28: 0.3588 | D28: 0.1701 | E28: 0.1408 | F28: 0.2516 | G28: 0.0578 | H28: 0.0209
A29: 2013: | B29: January | C29: 0.365 | D29: 0.1686 | E29: 0.0893 | F29: 0.2968 | G29: 0.0617 | H29: 0.01842
B30: February | C30: 0.36868489 | D30: 0.16327626 | E30: 0.084976228 | F30: 0.28072112 | G30: 0.067730078 | H30: 0.034611422
B31: March | C31: 0.38013154 | D31: 0.14221125 | E31: 0.088187465 | F31: 0.2906114 | G31: 0.066615748 | H31: 0.032242601
B32: April | C32: 0.38693613 | D32: 0.14913184 | E32: 0.081306312 | F32: 0.28565773 | G32: 0.065704441 | H32: 0.031263557
B33: May | C33: 0.38200297 | D33: 0.14654284 | E33: 0.08046472 | F33: 0.28414198 | G33: 0.074095477 | H33: 0.032752014
B34: June | C34: 0.36698699 | D34: 0.14580192 | E34: 0.09001753 | F34: 0.28612063 | G34: 0.079905023 | H34: 0.031167899
B35: July | C35: 0.37139827 | D35: 0.14864921 | E35: 0.084694808 | F35: 0.28993934 | G35: 0.07348656 | H35: 0.031831813
B36: August | C36: 0.37251525 | D36: 0.14243383 | E36: 0.085089289 | F36: 0.29090586 | G36: 0.077910444 | H36: 0.031145327
B37: September | C37: 0.374 | D37: 0.139 | E37: 0.089 | F37: 0.289 | G37: 0.078 | H37: 0.031
B38: October | C38: 0.377 | D38: 0.1368 | E38: 0.0869 | F38: 0.2894 | G38: 0.0781 | H38: 0.0311
B39: December | C39: 0.36391866 | D39: 0.14580696 | E39: 0.08570016 | F39: 0.29221132 | G39: 0.081599951 | H39: 0.030762944
A40: 2014: | B40: January | C40: 0.357 | D40: 0.143 | E40: 0.085 | F40: 0.3 | G40: 0.085 | H40: 0.03
...

Sheet Fixed rate bond (Values)
A1: 29 December 2023
B2: Sector code | C2: R186 (2026) | D2: R2030 (2030) | E2: R213 (2031) | F2: R2032 (2032) | G2: R2035 (2035) | H2: R209 (2036) | I2: R2037 (2037) | J2: R2040 (2040) | K2: R214 (2041) | L2: R2044 (2044) | M2: R2048 (2048) | N2: R2053 (2053) | O2: Total
B3: Foreign sector | C3: 1.3354722e+11 | D3: 91791253924 | E3: 61763034014 | F3: 79639729343 | G3: 101078056991 | H3: 32433218635 | I3: 85853164274 | J3: 67959096576 | K3: 46277899412 | L3: 71672658171 | M3: 88411302551 | N3: 7035577118 | O3: =SUM(C3:N3) -> 8.6746221e+11
B4: Monetary institutions | C4: 1.062315e+11 | D4: 9.2542437e+10 | E4: 46024406026 | F4: 6.4646078e+10 | G4: 2.6014263e+10 | H4: 12517119053 | I4: 2.6382729e+10 | J4: 30638281129 | K4: 15745946008 | L4: 2.5329482e+10 | M4: 1.2369253e+11 | N4: 5041949702 | O4: =SUM(C4:N4) -> 5.7480672e+11
B5: Long-term insurers | C5: 1.7439233e+10 | D5: 12304650837 | E5: 8000047789 | F5: 14816005320 | G5: 20717928611 | H5: 7072608899 | I5: 20493461121 | J5: 21518583852 | K5: 5679062000 | L5: 20390862062 | M5: 24114233549 | N5: 7487720502 | O5: =SUM(C5:N5) -> 1.800344e+11
B6: Short-term insurers | C6: 2419663148 | D6: 3866921466 | E6: 1341839834 | F6: 3346738450 | G6: 3179066671 | H6: 646710955 | I6: 3257414839 | J6: 1806502700 | K6: 665563315 | L6: 1585497196 | M6: 3746326362 | N6: 22485000 | O6: =SUM(C6:N6) -> 25884729936
B7: Private self-administered funds | C7: 2.7430096e+09 | D7: 6090762856 | E7: 3675470381 | F7: 11032139395 | G7: 11297753518 | H7: 4485043865 | I7: 8772914677 | J7: 7653320022 | K7: 1604007177 | L7: 8308493289 | M7: 8858935977 | N7: 658370665 | O7: =SUM(C7:N7) -> 7.5180221e+10
B8: Official pension funds | C8: 2.977808e+10 | D8: 49879237599 | E8: 18805703290 | F8: 44241731276 | G8: 39532931318 | H8: 15302331794 | I8: 55365274443 | J8: 37611846855 | K8: 8296556783 | L8: 49162398005 | M8: 63632124632 | N8: 492908289 | O8: =SUM(C8:N8) -> 4.1210112e+11
B9: Other financial institutions | C9: 6.3365213e+10 | D9: 8.6608666e+10 | E9: 44741190829 | F9: 85831889866 | G9: 8.9656871e+10 | H9: 27293895818 | I9: 74044256427 | J9: 55655429488 | K9: 13594962208 | L9: 70313923470 | M9: 7.5812988e+10 | N9: 12425578508 | O9: =SUM(C9:N9) -> 6.9934486e+11
B10: Other sector | C10: 1.6657651e+10 | D10: 13833086762 | E10: 2293969081 | F10: 6.598023e+09 | G10: 7220068315 | H10: 4507623126 | I10: 4.5931339e+09 | J10: 6059805029 | K10: 1517859593 | L10: 2.2163171e+09 | M10: 1839829706 | N10: 272666077 | O10: =SUM(C10:N10) -> 6.7610032e+10
B11: CSDP reporting error | C11: 468187481 | D11: 136643033 | E11: 251500000 | F11: 10570000 | G11: 353932440 | H11: 4000000 | I11: 1618300 | J11: 14482150 | K11: 0 | L11: 6880000 | M11: 272400000 | N11: 0 | O11: =SUM(C11:N11) -> 1520213404
C12: =SUM(C3:C11) -> 3.7264976e+11 | D12: =SUM(D3:D11) -> 357053660031 | E12: =SUM(E3:E11) -> 186897161244 | F12: =SUM(F3:F11) -> 310162904372 | G12: =SUM(G3:G11) -> 299050871436 | H12: =SUM(H3:H11) -> 104262552145 | I12: =SUM(I3:I11) -> 278763967029 | J12: =SUM(J3:J11) -> 228917347801 | ... O12: =SUM(O3:O11) -> 2.9039445e+12

Sheet Fixed rate bond % (Values)
A1: ='Fixed rate bond (Values)'!A1 -> 29 December 2023
B2: Sector code | C2: R186 (2026) | D2: R2030 (2030) | E2: R213 (2031) | F2: R2032 (2032) | G2: R2035 (2035) | H2: R209 (2036) | I2: R2037 (2037) | J2: R2040 (2040) | K2: R214 (2041) | L2: R2044 (2044) | M2: R2048 (2048) | N2: R2053 (2053) | O2: TOTAL
B3: Foreign sector | C3: 0.35837194 | D3: 0.25707972 | E3: 0.33046534 | F3: 0.25676742 | G3: 0.3379962 | H3: 0.31107256 | I3: 0.30797798 | J3: 0.29687176 | K3: 0.49557699 | L3: 0.28785759 | M3: 0.22647459 | N3: 0.21041132 | O3: 0.29871859
B4: Monetary institutions | C4: 0.28507063 | D4: 0.25918356 | E4: 0.24625524 | F4: 0.20842621 | G4: 0.086989423 | H4: 0.12005383 | I4: 0.094641819 | J4: 0.13383993 | K4: 0.1686189 | L4: 0.10173034 | M4: 0.31685106 | N4: 0.15078838 | O4: 0.19793998
B5: Long-term insurers | C5: 0.046797919 | D5: 0.034461629 | E5: 0.042804544 | F5: 0.047768463 | G5: 0.069278944 | H5: 0.067834604 | I5: 0.073515459 | J5: 0.094001543 | K5: 0.060815475 | L5: 0.081895449 | M5: 0.061771075 | N5: 0.22393346 | O5: 0.061996501
B6: Short-term insurers | C6: 0.0064931296 | D6: 0.010830085 | E6: 0.0071795624 | F6: 0.01079026 | G6: 0.010630521 | H6: 0.0062027156 | I6: 0.011685208 | J6: 0.0078915063 | K6: 0.0071273301 | L6: 0.0063678036 | M6: 0.009596598 | N6: 0.00067245351 | O6: 0.0089136448
B7: Private self-administered funds | C7: 0.0073608249 | D7: 0.017058396 | E7: 0.019665737 | F7: 0.035568855 | G7: 0.037778701 | H7: 0.043016824 | I7: 0.031470763 | J7: 0.033432678 | K7: 0.017176861 | L7: 0.033369251 | M7: 0.02269307 | N7: 0.019689734 | O7: 0.025889001
B8: Official pension funds | C8: 0.07990903 | D8: 0.13969675 | E8: 0.10062059 | F8: 0.1426403 | G8: 0.13219467 | H8: 0.14676729 | I8: 0.19860987 | J8: 0.16430317 | K8: 0.08884549 | L8: 0.19745005 | M8: 0.16300019 | N8: 0.01474129 | O8: 0.14191081
B9: Other financial institutions | C9: 0.17003959 | D9: 0.24256485 | E9: 0.23938935 | F9: 0.27673164 | G9: 0.29980475 | H9: 0.26178043 | I9: 0.26561631 | J9: 0.24312456 | K9: 0.14558462 | L9: 0.28240053 | M9: 0.19420272 | N9: 0.3716088 | O9: 0.24082584
B10: Other sector | C10: 0.044700554 | D10: 0.038742319 | E10: 0.012273964 | F10: 0.021272767 | G10: 0.024143278 | H10: 0.043233386 | I10: 0.016476785 | J10: 0.026471585 | K10: 0.016254331 | L10: 0.0089013541 | M10: 0.0047129119 | N10: 0.008154559 | O10: 0.023282136
B11: CSDP reporting error | C11: 0.001256374 | D11: 0.00038269607 | E11: 0.0013456598 | F11: 3.4078866e-05 | G11: 0.0011835192 | H11: 3.8364685e-05 | I11: 5.8052697e-06 | J11: 6.3263663e-05 | K11: 0 | L11: 2.7632019e-05 | M11: 0.00069778045 | N11: 0 | O11: 0.00052349947
C12: 1 | D12: 1 | E12: 1 | F12: 1 | G12: 1 | H12: 1 | I12: 1 | J12: 1 | K12: 1 | L12: 1 | M12: 1 | N12: 1 | O12: 1

Sheet ILB (Values)
A1: ='Fixed rate bond (Values)'!A1 -> 29 December 2023
B2: Sector code | C2: I2025 (2025) | D2: R210 (2028) | E2: I2029 (2029) | F2: I2031 (2031) | G2: I2033 (2033) | H2: R202 (2033) | I2: I2038 (2038) | J2: I2043 (2043) | K2: I2046 (2046) | L2: I2050 (2050) | M2: I2058 (2058) | N2: Amount
B3: Foreign sector | C3: 973172362 | D3: 78589432 | E3: 5287902366 | F3: 130800000 | G3: 14439499078 | H3: 226829735 | I3: 3127843812 | J3: 0 | K3: 4912648101 | L3: 1650124499 | M3: 0 | N3: =SUM(C3:M3) -> 30827409385
B4: Monetary institutions | C4: 11440781559 | D4: 2147314580 | E4: 3107475322 | F4: 401038813 | G4: 971172263 | H4: 5.4264274e+09 | I4: 7569347254 | J4: 0 | K4: 1.3438547e+10 | L4: 1.5660111e+10 | M4: 91000000 | N4: =SUM(C4:M4) -> 6.0253215e+10
B5: Long-term insurers | C5: 4.9048642e+09 | D5: 2259780469 | E5: 2891123727 | F5: 84200000 | G5: 3079580772 | H5: 1671375854 | I5: 5820784707 | J5: 0 | K5: 7651147214 | L5: 7274560353 | M5: 0 | N5: =SUM(C5:M5) -> 3.5637417e+10
B6: Short-term insurers | C6: 1.9688269e+09 | D6: 304121799 | E6: 1287877301 | F6: 8000000 | G6: 1253025803 | H6: 525603508 | I6: 1.2746765e+09 | J6: 0 | K6: 1238483946 | L6: 2.2101785e+09 | M6: 0 | N6: =SUM(C6:M6) -> 1.0070794e+10
B7: Private self-administered funds | C7: 4508679500 | D7: 2.2381215e+09 | E7: 4368674501 | F7: 27300000 | G7: 7241135612 | H7: 2.9824168e+09 | I7: 9718655857 | J7: 0 | K7: 11972423026 | L7: 1.4335812e+10 | M7: 119400000 | N7: =SUM(C7:M7) -> 5.7512619e+10
B8: Official pension funds | C8: 24764659765 | D8: 19715615590 | E8: 19264222477 | F8: 430000000 | G8: 35240282128 | H8: 23454099576 | I8: 46482710838 | J8: 4286000000 | K8: 42219324626 | L8: 49720428022 | M8: 160000000 | N8: =SUM(C8:M8) -> 265737343022
B9: Other financial institutions | C9: 18391218141 | D9: 4.2339664e+09 | E9: 16685340621 | F9: 579609286 | G9: 13181691863 | H9: 3.0892375e+09 | I9: 6.2796571e+09 | J9: 49720334 | K9: 1.1163436e+10 | L9: 1.2210855e+10 | M9: 276526831 | N9: =SUM(C9:M9) -> 8.6141259e+10
B10: Other sector | C10: 957797576 | D10: 6.7000781e+08 | E10: 259806406 | F10: 24051901 | G10: 1338273794 | H10: 565194678 | I10: 1736323883 | J10: 0 | K10: 2073990122 | L10: 2367931558 | M10: 0 | N10: =SUM(C10:M10) -> 9.9933777e+09
B11: CSDP reporting error | C11: 0 | D11: 300000 | E11: 0 | F11: 0 | G11: 0 | H11: 0 | I11: 0 | J11: 0 | K11: 0 | L11: 0 | M11: 0 | N11: =SUM(C11:M11) -> 300000
C12: =SUM(C3:C11) -> 67910000000 | D12: =SUM(D3:D11) -> 31647817562 | E12: =SUM(E3:E11) -> 53152422721 | F12: =SUM(F3:F11) -> 1685000000 | G12: =SUM(G3:G11) -> 76744661313 | H12: =SUM(H3:H11) -> 37941184999 | I12: =SUM(I3:I11) -> 82010000000 | J12: =SUM(J3:J11) -> 4335720334 | ... N12: =SUM(N3:N11) -> 556173733760

Sheet ILB % (Values)
A1: ='Fixed rate bond (Values)'!A1 -> 29 December 2023
C2: I2025 (2025) | D2: R210 (2028) | E2: I2029 (2029) | F2: I2031 (2031) | G2: I2033 (2033) | H2: R202 (2033) | I2: I2038 (2038) | J2: I2043 (2043) | K2: I2046 (2046) | L2: I2050 (2050) | M2: I2058 (2058) | N2: TOTAL
B3: Foreign sector | C3: 0.014330325 | D3: 0.0024832497 | E3: 0.099485632 | F3: 0.077626113 | G3: 0.18814988 | H3: 0.0059784568 | I3: 0.038139786 | J3: 0 | K3: 0.051892343 | L3: 0.015651375 | M3: 0 | N3: 0.055427661
B4: Monetary institutions | C4: 0.16846976 | D4: 0.067850321 | E4: 0.058463475 | F4: 0.23800523 | G4: 0.012654591 | H4: 0.14302208 | I4: 0.092297857 | J4: 0 | K4: 0.14195148 | L4: 0.14853562 | M4: 0.14066506 | N4: 0.10833524
B5: Long-term insurers | C5: 0.072225949 | D5: 0.071403991 | E5: 0.054393075 | F5: 0.049970326 | G5: 0.040127622 | H5: 0.044051757 | I5: 0.070976524 | J5: 0 | K5: 0.080819132 | L5: 0.06899896 | M5: 0 | N5: 0.064076052
B6: Short-term insurers | C6: 0.028991708 | D6: 0.0096095662 | E6: 0.024229889 | F6: 0.0047477745 | G6: 0.016327205 | H6: 0.013853113 | I6: 0.01554294 | J6: 0 | K6: 0.013082116 | L6: 0.020963469 | M6: 0 | N6: 0.018107281
B7: Private self-administered funds | C7: 0.066391982 | D7: 0.070719615 | E7: 0.082191446 | F7: 0.01620178 | G7: 0.094353607 | H7: 0.078606316 | I7: 0.11850574 | J7: 0 | K7: 0.1264648 | L7: 0.13597469 | M7: 0.18456492 | N7: 0.10340765
B8: Official pension funds | C8: 0.36466882 | D8: 0.6229692 | E8: 0.36243357 | F8: 0.25519288 | G8: 0.45918871 | H8: 0.61816993 | I8: 0.56679321 | J8: 0.98853239 | K8: 0.44596308 | L8: 0.47159659 | M8: 0.24732318 | N8: 0.47779556
B9: Other financial institutions | C9: 0.27081753 | D9: 0.13378383 | E9: 0.31391496 | F9: 0.34398177 | G9: 0.17176038 | H9: 0.081421745 | I9: 0.076571846 | J9: 0.011467606 | K9: 0.11791947 | L9: 0.11581955 | M9: 0.42744684 | N9: 0.15488193
B10: Other sector | C10: 0.014103925 | D10: 0.021170743 | E10: 0.0048879504 | F10: 0.014274125 | G10: 0.017438005 | H10: 0.014896601 | I10: 0.0211721 | J10: 0 | K10: 0.021907575 | L10: 0.022459751 | M10: 0 | N10: 0.017968086
B11: CSDP reporting error | C11: 0 | D11: 9.4793266e-06 | E11: 0 | F11: 0 | G11: 0 | H11: 0 | I11: 0 | J11: 0 | K11: 0 | L11: 0 | M11: 0 | N11: 5.393998e-07
C12: 1 | D12: 1 | E12: 1 | F12: 1 | G12: 1 | H12: 1 | I12: 1 | J12: 1 | K12: 1 | L12: 1 | M12: 1 | N12: 1

Sheet FRN (Values)
A1: ='Fixed rate bond (Values)'!A1 -> 29 December 2023
B2: Sector code | C2: RN2027 (2027) | D2: RN2030 (2030) | E2: Total
B3: Foreign sector | C3: 444814011 | D3: 92800000 | E3: =SUM(C3:D3) -> 537614011
B4: Monetary institutions | C4: 54794000000 | D4: 18554430000 | E4: =SUM(C4:D4) -> 73348430000
B5: Long-term insurers | C5: 945550000 | D5: 1214100000 | E5: =SUM(C5:D5) -> 2159650000
B6: Short-term insurers | C6: 1277700000 | D6: 69980000 | E6: =SUM(C6:D6) -> 1347680000
B7: Private self-administered funds | C7: 57020000 | D7: 63114909 | E7: =SUM(C7:D7) -> 120134909
B8: Official pension funds | C8: 1630000 | D8: 32645694 | E8: =SUM(C8:D8) -> 34275694
B9: Other financial institutions | C9: 10296387386 | D9: 9859346995 | E9: =SUM(C9:D9) -> 20155734381
B10: Other sector | C10: 177898603 | D10: 68582402 | E10: =SUM(C10:D10) -> 246481005
B11: CSDP reporting error | C11: 0 | D11: 0 | E11: =SUM(C11:D11) -> 0
C12: =SUM(C3:C11) -> 67995000000 | D12: =SUM(D3:D11) -> 29955000000 | E12: =SUM(E3:E11) -> 97950000000

Sheet FRN % (Values)
A1: ='Fixed rate bond (Values)'!A1 -> 29 December 2023
B3: Sector code | C3: RN2027 (2027) | D3: RN2030 (2030) | E3: TOTAL
B4: Foreign sector | C4: 0.0065418635 | D4: 0.0030979803 | E4: 0.0054886576
B5: Monetary institutions | C5: 0.80585337 | D5: 0.61941012 | E5: 0.74883543
B6: Long-term insurers | C6: 0.01390617 | D6: 0.040530796 | E6: 0.022048494
B7: Short-term insurers | C7: 0.018791088 | D7: 0.0023361709 | E7: 0.013758857
B8: Private self-administered funds | C8: 0.00083859107 | D8: 0.0021069908 | E8: 0.0012264922
B9: Official pension funds | C9: 2.3972351e-05 | D9: 0.0010898245 | E9: 0.00034993052
B10: Other financial institutions | C10: 0.1514286 | D10: 0.32913861 | E10: 0.20577575
B11: Other sector | C11: 0.0026163483 | D11: 0.0022895143 | E11: 0.0025163962
B12: CSDP reporting error | C12: 0 | D12: 0 | E12: 0
C13: 1 | D13: 1 | E13: 1
